Workbook

Sheet Tabela Preços 
B1: SAMSUNG
A2: (Novidade)
A3: REFERÊNCIA | B3: DESIGNAÇÃO | C3: EAN | D3: STOCK | E3: Família | F3: Preço com IVA
A4: RS90F64A2FFA | B4: FRIGORÍFICO SIDE BY SIDE FAMILY HUB ECRÃ 21,5" (594L) BLACK | C4: 8806097130642 | D4: =VLOOKUP(Tabela1[[#This Row],[REFERÊNCIA]],Folha1!$A$1:$G$642,4,FALSE) -> 25 | E4: Frigoríficos | F4: 3819000
A5: RS70F65K2TFA | B5: FRIGORÍFICO SIDE BY SIDE SAMSUNG (617L CINZA) | C5: 8806097130574 | D5: =VLOOKUP(Tabela1[[#This Row],[REFERÊNCIA]],Folha1!$A$1:$G$642,4,FALSE) -> 1 | E5: Frigoríficos | F5: 2451000
A6: RS80F64G2FFA | B6: FRIGORÍFICO SIDE BY SIDE SAMSUNG (609L PRETO) | C6: 8806097130611 | D6: =VLOOKUP(Tabela1[[#This Row],[REFERÊNCIA]],Folha1!$A$1:$G$642,4,FALSE) -> 4 | E6: Frigoríficos | F6: 3021000
A7: RS57DG4000B4FA | B7: Frigorífico Side by Side SAMSUNG (564L - Preto) | C7: 8806095754796 | D7: =VLOOKUP(Tabela1[[#This Row],[REFERÊNCIA]],Folha1!$A$1:$G$642,4,FALSE) -> 0 | E7: Frigoríficos | F7: 1710000
A8: RF48A4000M9/GH | B8: FRIGORÍFICO FRENCH DOOR SAMSUNG (511L - Cinza) | C8: 8806094628920 | D8: =VLOOKUP(Tabela1[[#This Row],[REFERÊNCIA]],Folha1!$A$1:$G$642,4,FALSE) -> 0 | E8: Frigoríficos | F8: 1790000
A9: RF48A400EB4/EF | B9: FRIGORÍFICO FRENCH DOOR SAMSUNG (511L - Preto) | C9: 8806095057866 | D9: =VLOOKUP(Tabela1[[#This Row],[REFERÊNCIA]],Folha1!$A$1:$G$642,4,FALSE) -> 8 | E9: Frigoríficos | F9: 1890000
A10: RF49A5202B1/FA | B10: FRIGORÍFICO FRENCH DOOR SAMSUNG (470L - Preto) | C10: 8806090956508 | D10: =VLOOKUP(Tabela1[[#This Row],[REFERÊNCIA]],Folha1!$A$1:$G$642,4,FALSE) -> 1 | E10: Frigoríficos | F10: 1926600
A11: RF29BB8600MTFA | B11: FRIGORÍFICO PREMIUM 4 PORTAS SAMSUNG (630L - PRETO) WIFI | C11: 8806094050547 | D11: =VLOOKUP(Tabela1[[#This Row],[REFERÊNCIA]],Folha1!$A$1:$G$642,4,FALSE) -> 0 | E11: Frigoríficos | F11: 2070917
A12: RF71DB975012FA | B12: FRIGORÍFICO PREMIUM 4 PORTAS SAMSUNG (704L - BRANCO&PRETO) | C12: 8806095424149 | D12: =VLOOKUP(Tabela1[[#This Row],[REFERÊNCIA]],Folha1!$A$1:$G$642,4,FALSE) -> 0 | E12: Frigoríficos | F12: 3990000
A13: RF71A967532/UT | B13: FRIGORÍFICO PREMIUM 4 PORTAS SAMSUNG (820L - ROSA) | C13: 8806092113299 | D13: =VLOOKUP(Tabela1[[#This Row],[REFERÊNCIA]],Folha1!$A$1:$G$642,4,FALSE) -> 0 | E13: Frigoríficos | F13: 3980000
A14: RR39M71407F/FA | B14: FRIGORÍFICO 1 PORTA SAMSUNG (385L - CINZA) | C14: 8806088602592 | D14: =VLOOKUP(Tabela1[[#This Row],[REFERÊNCIA]],Folha1!$A$1:$G$642,4,FALSE) -> 1 | E14: Frigoríficos | F14: 1225500
A15: WW70T4020CX/NQ | B15: MAQ DE LAVAR ROUPA FL SAMSUNG (7KG - Inox) | C15: 8806092079731 | D15: =VLOOKUP(Tabela1[[#This Row],[REFERÊNCIA]],Folha1!$A$1:$G$642,4,FALSE) -> 37 | E15: Máquinas de Lavar | F15: 1099000
... A149: SP-LFF3CLAXXXA | B149: PROJECTOR SAMSUNG SMART THE FREESTYLE 100" GEN2 | C149: 8806094953268 | D149: =VLOOKUP(Tabela1[[#This Row],[REFERÊNCIA]],Folha1!$A$1:$G$642,4,FALSE) -> 4 | E149: Televisores | F149: 999000
B150: FHD
A151: UA32H5000FUXLY | B151: TV SAMSUNG 32" FHD - 32H5000 Smart TV EG | C151: 8806097016502 | D151: =VLOOKUP(Tabela1[[#This Row],[REFERÊNCIA]],Folha1!$A$1:$G$642,4,FALSE) -> 32 | E151: Televisores | F151: 330000
A152: UA32N5000AUXLY | B152: TV SAMSUNG 32" FHD - 32N5000 | C152: 8801643265687 | D152: =VLOOKUP(Tabela1[[#This Row],[REFERÊNCIA]],Folha1!$A$1:$G$642,4,FALSE) -> 4 | E152: Televisores | F152: 259000
B153: UHD
A154: UA43U8000FUXLY | B154: TV SAMSUNG 43" UHD 4K FLAT SMART TV - U8000 (2025) EG | C154: 8806097191957 | D154: =VLOOKUP(Tabela1[[#This Row],[REFERÊNCIA]],Folha1!$A$1:$G$642,4,FALSE) -> 15 | E154: Televisores | F154: 599000
A155: UA43U8000HUXLY | B155: TV SAMSUNG 43" UHD 4K FLAT SMART TV - U8000 (2026) EG | C155: 8806099026592 | D155: =VLOOKUP(Tabela1[[#This Row],[REFERÊNCIA]],Folha1!$A$1:$G$642,4,FALSE) -> 10 | E155: Televisores | F155: 635158
A156: UA43U8000HUXLY | B156: TV SAMSUNG 43" UHD 4K FLAT SMART TV - U8000 (2026) EG | C156: 8806099026592 | D156: =VLOOKUP(Tabela1[[#This Row],[REFERÊNCIA]],Folha1!$A$1:$G$642,4,FALSE) -> 10 | E156: Televisores | F156: 635158
A157: UA50U8000FUXLY | B157: TV SAMSUNG 50" UHD 4K FLAT SMART TV - U8000 (2025) EG | C157: 8806097191995 | D157: =VLOOKUP(Tabela1[[#This Row],[REFERÊNCIA]],Folha1!$A$1:$G$642,4,FALSE) -> 57 | E157: Televisores | F157: 729000
A158: UA55U8000HUXLY | B158: TV SAMSUNG 55" UHD 4K FLAT SMART TV - U8000 (2026) EG | C158: 8806099026646 | D158: =VLOOKUP(Tabela1[[#This Row],[REFERÊNCIA]],Folha1!$A$1:$G$642,4,FALSE) -> 78 | E158: Televisores | F158: 965440
A159: UA50CU7000KXLY | B159: TV SAMSUNG 50" UHD 4K FLAT SMART TV - CU7000 (2023) | C159: 8806094932270 | D159: =VLOOKUP(Tabela1[[#This Row],[REFERÊNCIA]],Folha1!$A$1:$G$642,4,FALSE) -> 0 | E159: Televisores | F159: 749000
A160: UA65U8000FUXKE | B160: TV SAMSUNG 65" Crystal UHD 4K FLAT SMART TV U8000 (2025) EG | C160: 8806097192039 | D160: =VLOOKUP(Tabela1[[#This Row],[REFERÊNCIA]],Folha1!$A$1:$G$642,4,FALSE) -> 21 | E160: Televisores | F160: 1179000
A161: UA65U8000HUXLY | B161: TV SAMSUNG 65" Crystal UHD 4K FLAT SMART TV U8000 (2026) EG | C161: 8806099026783 | D161: =VLOOKUP(Tabela1[[#This Row],[REFERÊNCIA]],Folha1!$A$1:$G$642,4,FALSE) -> 17 | E161: Televisores | F161: 1244900
A162: UA75CU8000KXXA | B162: TV SAMSUNG 75" CRYSTAL UHD 4K FLAT SMART TV CU8000 (2023) SA | C162: 8806094832921 | D162: =VLOOKUP(Tabela1[[#This Row],[REFERÊNCIA]],Folha1!$A$1:$G$642,4,FALSE) -> 1 | E162: Televisores | F162: 2449000
A163: UA75U8000FUXLY | B163: TV SAMSUNG 75" UHD 4K FLAT SMART TV - U8000 (2025) EG | C163: 8806097198895 | D163: =VLOOKUP(Tabela1[[#This Row],[REFERÊNCIA]],Folha1!$A$1:$G$642,4,FALSE) -> 3 | E163: Televisores | F163: 1899000
A164: UA75U8000HUXLY | B164: TV SAMSUNG 65" Crystal UHD 4K FLAT SMART TV U8000 (2026) EG | C164: 8806099026837 | D164: =VLOOKUP(Tabela1[[#This Row],[REFERÊNCIA]],Folha1!$A$1:$G$642,4,FALSE) -> 28 | E164: Televisores | F164: 1930880
A165: UA85DU8000UXLY | B165: TV SAMSUNG 85" CRYSTAL UHD 4K FLAT SMART TV - DU8000 (2024) | C165: 8806097198895 | D165: =VLOOKUP(Tabela1[[#This Row],[REFERÊNCIA]],Folha1!$A$1:$G$642,4,FALSE) -> 2 | E165: Televisores | F165: 4299000
... A170: UA98DU9000UXLY | B170: TV SAMSUNG 98" 4K UHD FLAT - DU9000 (2026) EG | C170: 8806095597676 | D170: =VLOOKUP(Tabela1[[#This Row],[REFERÊNCIA]],Folha1!$A$1:$G$642,4,FALSE) -> 8 | E170: Televisores | F170: 5999000
B171: MINI LED
A172: UA65M80HAUXLY | B172: TV SAMSUNG 65" MINI LED M80H 4K VISION AI SMART TV (2026) | C172: 8806099063146 | D172: =VLOOKUP(Tabela1[[#This Row],[REFERÊNCIA]],Folha1!$A$1:$G$642,4,FALSE) -> 9 | E172: Televisores | F172: 1860000
A173: UA75M80HAUXLY | B173: TV SAMSUNG 75" MINI LED M80H 4K VISION AI SMART TV (2026) | C173: 8806099063153 | D173: =VLOOKUP(Tabela1[[#This Row],[REFERÊNCIA]],Folha1!$A$1:$G$642,4,FALSE) -> 12 | E173: Televisores | F173: 2490000
B174: QLED
A175: QA43LS01DAKXXA | B175: TV SAMSUNG 43" The Serif - LS01D | C175: 8806095568683 | D175: =VLOOKUP(Tabela1[[#This Row],[REFERÊNCIA]],Folha1!$A$1:$G$642,4,FALSE) -> 14 | E175: Televisores | F175: 1299000
A176: QA55LS01DAKXXA | B176: TV SAMSUNG 55" The Serif - LS01D | C176: 8806094293753 | D176: =VLOOKUP(Tabela1[[#This Row],[REFERÊNCIA]],Folha1!$A$1:$G$642,4,FALSE) -> 8 | E176: Televisores | F176: 1999000
A177: QA55Q7FAAUXLY | B177: TV SAMSUNG 55" QLED - Q7F (Smart TV AI - 2025) | C177: 8806097194040 | D177: =VLOOKUP(Tabela1[[#This Row],[REFERÊNCIA]],Folha1!$A$1:$G$642,4,FALSE) -> 3 | E177: Televisores | F177: 1547208
...

Sheet Folha1
A1: Ref | B1: Design | C1: Desc_familia | D1: Stock | E1: Pv1 | F1: Pv2 | G1: Pv5
A2: RT25HAR4DSA/GH | B2: FRIGORÍFICO TOP FREEZER INVERTER SAMSUNG (255L - PRETA) | C2: Frigorificos | D2: 0 | E2: 0 | F2: 0 | G2: 0
A3: RS90F64A2FFA | B3: Frigorífico Side-by-Side Family Hub ecrã 21.5" (594L) Black | C3: Frigorificos | D3: 25 | E3: 3350000 | F3: 3098800 | G3: 3819000
A4: RF48A4000B4/ME | B4: FRIGORÍFICO FRENCH DOOR SAMSUNG (511L - Preto) | C4: Frigorificos | D4: 0 | E4: 1657894.7 | F4: 1376368.4 | G4: 1890000
A5: RF48A4000M9/MA | B5: FRIGORÍFICO FRENCH DOOR SAMSUNG (511L - Cinza) | C5: Frigorificos | D5: 0 | E5: 1298245.6 | F5: 1056815.8 | G5: 1480000
A6: RT53K6541BS/PE | B6: FRIGORÍFICO TOP FREEZER C/ DISP. AGUA SAMSUNG (526L - PRETO) | C6: Frigorificos | D6: 0 | E6: 1226315.8 | F6: 1005957.2 | G6: 1398000
A7: RS70F65K2TFA | B7: FRIGORÍFICO SIDE BY SIDE SAMSUNG (617L CINZA) | C7: Frigorificos | D7: 1 | E7: 2150000 | F7: 1959887.4 | G7: 2451000
A8: RS80F64G2FFA | B8: FRIGORÍFICO SIDE BY SIDE SAMSUNG (609L PRETO) | C8: Frigorificos | D8: 4 | E8: 2650000 | F8: 2463484.8 | G8: 3021000
A9: RS57DG4000B4FA | B9: Frigorífico Side by Side SAMSUNG (564L - Preto) | C9: Frigorificos | D9: 0 | E9: 1500000 | F9: 1345106.3 | G9: 1710000
A10: RF49A5202B1/FA | B10: FRIGORÍFICO FRENCH DOOR SAMSUNG (470L - Preto) | C10: Frigorificos | D10: 1 | E10: 1690000 | F10: 1569654 | G10: 1926600
A11: RR39M71407F/FA | B11: FRIGORÍFICO 1 PORTA SAMSUNG (385L - CINZA) | C11: Frigorificos | D11: 1 | E11: 1075000 | F11: 963593.15 | G11: 1225500
A12: RS65R5691M9 | B12: FRIGORÍFICO SIDE BY SIDE SAMSUNG (602L - CINZENTA) | C12: Frigorificos | D12: 0 | E12: 2614035.1 | F12: 2119346.8 | G12: 2980000
A13: RS64R53112A | B13: FRIGORÍFICO SIDE BY SIDE SAMSUNG (617L - PRETO ESPELHADO) | C13: Frigorificos | D13: 0 | E13: 2614035.1 | F13: 2099813.6 | G13: 2980000
... A62: SM-A145FZKDAFA | B62: Galaxy A14 LTE DS 4+64GB PRETO | C62: Telemoveis | D62: 1 | E62: 197368.42 | F62: 165322.24 | G62: 225000
A63: 1006002 | B63: Telefone Fixo Unitel 4G | C63: Telemoveis | D63: 0 | E63: 0 | F63: 0 | G63: 0
A64: MGYR3ZM/A | B64: Smart Cover for IPAD - Cyprus Green | C64: Telemoveis | D64: 0 | E64: 0 | F64: 0 | G64: 0
A65: MGYQ3ZM/A | B65: Smart Cover for IPAD - Deep Navy | C65: Telemoveis | D65: 0 | E65: 0 | F65: 0 | G65: 0
A66: MGYT3ZM/A | B66: Smart Cover for IPAD - Pink Navy | C66: Telemoveis | D66: 0 | E66: 0 | F66: 0 | G66: 0
A67: MXTF2ZM/A | B67: Smart Cover for IPAD - Surf Blue | C67: Telemoveis | D67: 0 | E67: 0 | F67: 0 | G67: 0
A68: SM-A705FZBUXFE | B68: Galaxy A70 LTE DS 4+128GB AZUL | C68: Telemoveis | D68: 0 | E68: 0 | F68: 0 | G68: 0
A69: SM-A207FZKDXFE | B69: Galaxy A20s LTE DS 3+32GB PRETO | C69: Telemoveis | D69: 0 | E69: 0 | F69: 0 | G69: 0
A70: SM-A107FZKDXFE | B70: Galaxy A10s LTE DS 2+32GB PRETO | C70: Telemoveis | D70: 0 | E70: 0 | F70: 0 | G70: 0
A71: SM-A165FZKDAFA | B71: Galaxy A16 LTE DS 4+128GB PRETO | C71: Telemoveis | D71: 0 | E71: 227192.98 | F71: 205878.75 | G71: 259000
A72: SM-A307FZKVSRR | B72: Galaxy A30s LTE DS 4+64GB PRETO | C72: Telemoveis | D72: 0 | E72: 0 | F72: 0 | G72: 0
A73: SM-A107FZBDXFE | B73: Galaxy A10s LTE DS 2+32GB AZUL | C73: Telemoveis | D73: 0 | E73: 0 | F73: 0 | G73: 0
A74: SM-A065FZKGAFA | B74: Galaxy A06 DS 4+ 128GB PRETO | C74: Telemoveis | D74: 0 | E74: 175000 | F74: 136247.27 | G74: 199500
A75: SM-X115NZSAAFA | B75: Galaxy Tablet A9 4+64 4G+WIFI Cinza | C75: Telemoveis | D75: 0 | E75: 288596.49 | F75: 267411.38 | G75: 329000
... A501: SM-R530NZAAXFA | B501: Auscultadores Galaxy BUDS3 Cinza | C501: Wearables and Acessories | D501: 0 | E501: 232017.54 | F501: 195904.7 | G501: 264500
A502: 19901083 | B502: DRONE DJI MINI 4 PRO FLY MORE COMBO (DJI RC2) | C502: Wearables and Acessories | D502: 0 | E502: 0 | F502: 0 | G502: 0
A503: 4Y51J62544 | B503: MOUSE LENOVO BLUETOOTH PROFISSIONAL EAN 0195892054498 | C503: Wearables and Acessories | D503: 0 | E503: 0 | F503: 0 | G503: 0
A504: EF-VS938PBEGWW | B504: Capa Galaxy S25 Ultra Kindsuit (Preto) | C504: Wearables and Acessories | D504: 1 | E504: 57017.54 | F504: 42250 | G504: 65000
A505: EF-GS918TBEGWW | B505: Capa Silicone SAMSUNG Galaxy S23 Ultra Preto c/Grip | C505: Wearables and Acessories | D505: 0 | E505: 34035.088 | F505: 28023.75 | G505: 38800
A506: EF-GS911TBEGWW | B506: Capa Silicone SAMSUNG Galaxy S23 Preto c/Grip | C506: Wearables and Acessories | D506: 1 | E506: 31578.947 | F506: 28023.75 | G506: 36000
A507: SM-R180NZKAXFA | B507: Auscultadores Galaxy BUDS LIVE PRETO | C507: Wearables and Acessories | D507: 0 | E507: 104385.96 | F507: 101920.63 | G507: 119000
A508: SM-R180NZNAXFA | B508: Auscultadores Galaxy BUDS LIVE BRONZE | C508: Wearables and Acessories | D508: 0 | E508: 171052.63 | F508: 130059.39 | G508: 195000
A509: EF-QA566CTEGWW | B509: Capa Galaxy A56 Transparente | C509: Wearables and Acessories | D509: 6 | E509: 17105.26 | F509: 13750.32 | G509: 19500
A510: EF-QA366CTEGWW | B510: Capa Galaxy A36 Transparente | C510: Wearables and Acessories | D510: 22 | E510: 17105.26 | F510: 13750.32 | G510: 19500
A511: SM-R540NZWAXFA | B511: Auscultadores Galaxy Buds 4 Branco | C511: Wearables and Acessories | D511: 29 | E511: 179318.08 | F511: 168110.7 | G511: 204422.61
A512: SM-R640NZKAXFA | B512: Auscultadores Galaxy Buds 4 Pro Preto | C512: Wearables and Acessories | D512: 37 | E512: 290000 | F512: 260000 | G512: 350000
A513: EF-QA107TTEGWW | B513: Capa Galaxy A10s Protective | C513: Wearables and Acessories | D513: 17 | E513: 877.19 | F513: 701.75 | G513: 1000
...
